Workbook

Sheet Start here
A1: Pathfinder Explorers - questionnaire tracker
A2: One copy of this workbook per cohort.
A4: How to use it
A5: 1. After each questionnaire, type every student's form into the Answers sheet: one row per form.
A6: 2. Yellow cells are the ones you type in. Everything else is worked out for you.
A7: 3. Summary shows the whole class at Start, Halfway and Finish. Growth shows each student.
A8: 4. Type each Explorer code once in column A of the Growth sheet.
A9: 5. The grey rows coded EXAMPLE show the format. They are left out of the Summary. Delete them whenever you like.
A11: How to type each answer
A12: Checkpoint | B12: Start, Halfway or Finish (pick from the list)
A13: A1 to A8 | B13: Part 1. Not true for me = 1, A little true = 2, Mostly true = 3, Very true = 4
A14: K1 to K8 | B14: Part 2. Right = 1. Wrong, or "I don't know yet" = 0. Left blank = leave the cell empty.
A15: LIKE1 to LIKE12 | B15: Part 3. Not much = 1, OK = 2, Loved it = 3
A16: HARD1 to HARD12 | B16: Part 3. Too easy = 1, Just right = 2, Too hard = 3
A17: PACE | B17: Too slow = 1, Just right = 2, Too fast = 3
A18: FAIR, SAFE | B18: Yes, Sometimes or No (pick from the list)
A19: FRIEND, MORE | B19: Yes, Maybe or No (pick from the list)
A20: NOTES | B20: Copy any Part 4 answer worth discussing, word for word
A22: Part 1: the sentences
A23: A1 | B23: I am good at figuring out how things work. | C23: Confidence
A24: A2 | B24: I could write a program that makes a robot do something. | C24: Confidence
A25: A3 | B25: When my code doesn't work, I can find the bug and fix it. | C25: Confidence
A26: A4 | B26: I keep trying when a problem is hard. | C26: Never give up
A27: A5 | B27: I can explain my ideas to my team. | C27: Teamwork
A28: A6 | B28: I like working with a team. | C28: Teamwork
A29: A7 | B29: Robots and coding are fun. | C29: Interest
A30: A8 | B30: I could be an engineer or a programmer one day. | C30: Interest
A32: Part 2: answer key
A33: K1 | B33: A robot is a machine that can... | C33: sense, think and act (Lesson 1)
A34: K2 | B34: In a program, loop() runs... | C34: over and over, forever (Lesson 2)
A35: K3 | B35: Red light and green light mixed together make... | C35: yellow (Lesson 3)
A36: K4 | B36: A Pathfinder turns right by... | C36: making its left wheels go faster (Lesson 5)
A37: K5 | B37: 1000 milliseconds is... | C37: 1 second (Lesson 6)
A38: K6 | B38: A function is... | C38: a move you invent and give a name (Lesson 7)
A39: K7 | B39: In if (buttonA()) { ... } else { ... } the else part happens when... | C39: A is NOT held down (Lesson 8)
A40: K8 | B40: While a program is waiting in delay(), it... | C40: can NOT read the stick (Lesson 10)
A42: Reading the results
A43: With a class of twelve, every number is a conversation starter, not a statistic. Look for big changes and for anything a lot of students agree on.
A44: Part 2 should climb from Start to Finish. A question most students still miss at Finish points at a lesson worth strengthening.
A45: Any SAFE = No is worth a quiet conversation the same week, not a spreadsheet.
...

Sheet Answers
A1: Who and when | D1: Part 1: About me (1 to 4) | L1: Part 2: right = 1, wrong = 0 | T1: Liked it? (1 to 3) | AF1: How hard? (1 to 3) | AR1: Part 3 questions | AW1: Notes
A2: Explorer code | B2: Checkpoint | C2: Date | D2: A1 | E2: A2 | F2: A3 | G2: A4 | H2: A5 | I2: A6 | J2: A7 | K2: A8 | L2: K1 | M2: K2 | N2: K3 | O2: K4 | P2: K5 | Q2: K6 | R2: K7 | S2: K8 | T2: LIKE1 | U2: LIKE2 | V2: LIKE3 | W2: LIKE4 | X2: LIKE5 | Y2: LIKE6 | Z2: LIKE7 | AA2: LIKE8 | AB2: LIKE9 | AC2: LIKE10 | AD2: LIKE11 | AE2: LIKE12 | AF2: HARD1 | AG2: HARD2 | AH2: HARD3 | AI2: HARD4 | AJ2: HARD5 | AK2: HARD6 | AL2: HARD7 | AM2: HARD8 | AN2: HARD9 | AO2: HARD10 | AP2: HARD11 | AQ2: HARD12 | AR2: PACE | AS2: FAIR | AT2: SAFE | AU2: FRIEND | AV2: MORE | AW2: Anything worth keeping from Part 4
A3: EXAMPLE | B3: Start | C3: 2026-09-08 | D3: 2 | E3: 1 | F3: 1 | G3: 3 | H3: 2 | I3: 3 | J3: 4 | K3: 2 | L3: 1 | M3: 1 | N3: 0 | O3: 0 | P3: 1 | Q3: 0 | R3: 0 | S3: 0
A4: EXAMPLE | B4: Finish | C4: 2026-11-24 | D4: 3 | E4: 3 | F4: 3 | G4: 3 | H4: 3 | I4: 4 | J4: 4 | K4: 3 | L4: 1 | M4: 1 | N4: 1 | O4: 1 | P4: 1 | Q4: 1 | R4: 1 | S4: 0 | Z4: 3 | AA4: 2 | AB4: 3 | AC4: 3 | AD4: 2 | AE4: 3 | AL4: 2 | AM4: 2 | AN4: 3 | AO4: 2 | AP4: 2 | AQ4: 2 | AR4: 2 | AS4: Yes | AT4: Yes | AU4: Yes | AV4: Maybe | AW4: Favorite was Mission to Mars because we planned it ourselves

Sheet Summary
A1: Whole class, at each checkpoint
A2: Rows coded EXAMPLE are left out. Blank = no answers yet.
A4: Forms entered | B4: Start | C4: Halfway | D4: Finish
A5: Number of questionnaires | B5: =COUNTIFS(Answers!$B$3:$B$400,"Start",Answers!$A$3:$A$400,"<>EXAMPLE",Answers!$A$3:$A$400,"<>") | C5: =COUNTIFS(Answers!$B$3:$B$400,"Halfway",Answers!$A$3:$A$400,"<>EXAMPLE",Answers!$A$3:$A$400,"<>") | D5: =COUNTIFS(Answers!$B$3:$B$400,"Finish",Answers!$A$3:$A$400,"<>EXAMPLE",Answers!$A$3:$A$400,"<>")
A7: Part 1: About me (average, 1 to 4) | B7: Start | C7: Halfway | D7: Finish | E7: Change
A8: Confidence | B8: =IFERROR(SUMPRODUCT((Answers!$B$3:$B$400="Start")*(Answers!$A$3:$A$400<>"EXAMPLE")*Answers!$D$3:$F$400)/SUMPRODUCT((Answers!$B$3:$B$400="Start")*(Answers!$A$3:$A$400<>"EXAMPLE")*(Answers!$D$3:$F$400<>"")),"") | C8: =IFERROR(SUMPRODUCT((Answers!$B$3:$B$400="Halfway")*(Answers!$A$3:$A$400<>"EXAMPLE")*Answers!$D$3:$F$400)/SUMPRODUCT((Answers!$B$3:$B$400="Halfway")*(Answers!$A$3:$A$400<>"EXAMPLE")*(Answers!$D$3:$F$400<>"")),"") | D8: =IFERROR(SUMPRODUCT((Answers!$B$3:$B$400="Finish")*(Answers!$A$3:$A$400<>"EXAMPLE")*Answers!$D$3:$F$400)/SUMPRODUCT((Answers!$B$3:$B$400="Finish")*(Answers!$A$3:$A$400<>"EXAMPLE")*(Answers!$D$3:$F$400<>"")),"") | E8: =IF(OR(B8="",D8=""),"",D8-B8)
A9: A1 I am good at figuring out how things work. | B9: =IFERROR(AVERAGEIFS(Answers!$D$3:$D$400,Answers!$B$3:$B$400,"Start",Answers!$A$3:$A$400,"<>EXAMPLE"),"") | C9: =IFERROR(AVERAGEIFS(Answers!$D$3:$D$400,Answers!$B$3:$B$400,"Halfway",Answers!$A$3:$A$400,"<>EXAMPLE"),"") | D9: =IFERROR(AVERAGEIFS(Answers!$D$3:$D$400,Answers!$B$3:$B$400,"Finish",Answers!$A$3:$A$400,"<>EXAMPLE"),"") | E9: =IF(OR(B9="",D9=""),"",D9-B9)
A10: A2 I could write a program that makes a robot do something. | B10: =IFERROR(AVERAGEIFS(Answers!$E$3:$E$400,Answers!$B$3:$B$400,"Start",Answers!$A$3:$A$400,"<>EXAMPLE"),"") | C10: =IFERROR(AVERAGEIFS(Answers!$E$3:$E$400,Answers!$B$3:$B$400,"Halfway",Answers!$A$3:$A$400,"<>EXAMPLE"),"") | D10: =IFERROR(AVERAGEIFS(Answers!$E$3:$E$400,Answers!$B$3:$B$400,"Finish",Answers!$A$3:$A$400,"<>EXAMPLE"),"") | E10: =IF(OR(B10="",D10=""),"",D10-B10)
A11: A3 When my code doesn't work, I can find the bug and fix it. | B11: =IFERROR(AVERAGEIFS(Answers!$F$3:$F$400,Answers!$B$3:$B$400,"Start",Answers!$A$3:$A$400,"<>EXAMPLE"),"") | C11: =IFERROR(AVERAGEIFS(Answers!$F$3:$F$400,Answers!$B$3:$B$400,"Halfway",Answers!$A$3:$A$400,"<>EXAMPLE"),"") | D11: =IFERROR(AVERAGEIFS(Answers!$F$3:$F$400,Answers!$B$3:$B$400,"Finish",Answers!$A$3:$A$400,"<>EXAMPLE"),"") | E11: =IF(OR(B11="",D11=""),"",D11-B11)
A12: Never give up | B12: =IFERROR(SUMPRODUCT((Answers!$B$3:$B$400="Start")*(Answers!$A$3:$A$400<>"EXAMPLE")*Answers!$G$3:$G$400)/SUMPRODUCT((Answers!$B$3:$B$400="Start")*(Answers!$A$3:$A$400<>"EXAMPLE")*(Answers!$G$3:$G$400<>"")),"") | C12: =IFERROR(SUMPRODUCT((Answers!$B$3:$B$400="Halfway")*(Answers!$A$3:$A$400<>"EXAMPLE")*Answers!$G$3:$G$400)/SUMPRODUCT((Answers!$B$3:$B$400="Halfway")*(Answers!$A$3:$A$400<>"EXAMPLE")*(Answers!$G$3:$G$400<>"")),"") | D12: =IFERROR(SUMPRODUCT((Answers!$B$3:$B$400="Finish")*(Answers!$A$3:$A$400<>"EXAMPLE")*Answers!$G$3:$G$400)/SUMPRODUCT((Answers!$B$3:$B$400="Finish")*(Answers!$A$3:$A$400<>"EXAMPLE")*(Answers!$G$3:$G$400<>"")),"") | E12: =IF(OR(B12="",D12=""),"",D12-B12)
A13: A4 I keep trying when a problem is hard. | B13: =IFERROR(AVERAGEIFS(Answers!$G$3:$G$400,Answers!$B$3:$B$400,"Start",Answers!$A$3:$A$400,"<>EXAMPLE"),"") | C13: =IFERROR(AVERAGEIFS(Answers!$G$3:$G$400,Answers!$B$3:$B$400,"Halfway",Answers!$A$3:$A$400,"<>EXAMPLE"),"") | D13: =IFERROR(AVERAGEIFS(Answers!$G$3:$G$400,Answers!$B$3:$B$400,"Finish",Answers!$A$3:$A$400,"<>EXAMPLE"),"") | E13: =IF(OR(B13="",D13=""),"",D13-B13)
A14: Teamwork | B14: =IFERROR(SUMPRODUCT((Answers!$B$3:$B$400="Start")*(Answers!$A$3:$A$400<>"EXAMPLE")*Answers!$H$3:$I$400)/SUMPRODUCT((Answers!$B$3:$B$400="Start")*(Answers!$A$3:$A$400<>"EXAMPLE")*(Answers!$H$3:$I$400<>"")),"") | C14: =IFERROR(SUMPRODUCT((Answers!$B$3:$B$400="Halfway")*(Answers!$A$3:$A$400<>"EXAMPLE")*Answers!$H$3:$I$400)/SUMPRODUCT((Answers!$B$3:$B$400="Halfway")*(Answers!$A$3:$A$400<>"EXAMPLE")*(Answers!$H$3:$I$400<>"")),"") | D14: =IFERROR(SUMPRODUCT((Answers!$B$3:$B$400="Finish")*(Answers!$A$3:$A$400<>"EXAMPLE")*Answers!$H$3:$I$400)/SUMPRODUCT((Answers!$B$3:$B$400="Finish")*(Answers!$A$3:$A$400<>"EXAMPLE")*(Answers!$H$3:$I$400<>"")),"") | E14: =IF(OR(B14="",D14=""),"",D14-B14)
A15: A5 I can explain my ideas to my team. | B15: =IFERROR(AVERAGEIFS(Answers!$H$3:$H$400,Answers!$B$3:$B$400,"Start",Answers!$A$3:$A$400,"<>EXAMPLE"),"") | C15: =IFERROR(AVERAGEIFS(Answers!$H$3:$H$400,Answers!$B$3:$B$400,"Halfway",Answers!$A$3:$A$400,"<>EXAMPLE"),"") | D15: =IFERROR(AVERAGEIFS(Answers!$H$3:$H$400,Answers!$B$3:$B$400,"Finish",Answers!$A$3:$A$400,"<>EXAMPLE"),"") | E15: =IF(OR(B15="",D15=""),"",D15-B15)
A16: A6 I like working with a team. | B16: =IFERROR(AVERAGEIFS(Answers!$I$3:$I$400,Answers!$B$3:$B$400,"Start",Answers!$A$3:$A$400,"<>EXAMPLE"),"") | C16: =IFERROR(AVERAGEIFS(Answers!$I$3:$I$400,Answers!$B$3:$B$400,"Halfway",Answers!$A$3:$A$400,"<>EXAMPLE"),"") | D16: =IFERROR(AVERAGEIFS(Answers!$I$3:$I$400,Answers!$B$3:$B$400,"Finish",Answers!$A$3:$A$400,"<>EXAMPLE"),"") | E16: =IF(OR(B16="",D16=""),"",D16-B16)
A17: Interest | B17: =IFERROR(SUMPRODUCT((Answers!$B$3:$B$400="Start")*(Answers!$A$3:$A$400<>"EXAMPLE")*Answers!$J$3:$K$400)/SUMPRODUCT((Answers!$B$3:$B$400="Start")*(Answers!$A$3:$A$400<>"EXAMPLE")*(Answers!$J$3:$K$400<>"")),"") | C17: =IFERROR(SUMPRODUCT((Answers!$B$3:$B$400="Halfway")*(Answers!$A$3:$A$400<>"EXAMPLE")*Answers!$J$3:$K$400)/SUMPRODUCT((Answers!$B$3:$B$400="Halfway")*(Answers!$A$3:$A$400<>"EXAMPLE")*(Answers!$J$3:$K$400<>"")),"") | D17: =IFERROR(SUMPRODUCT((Answers!$B$3:$B$400="Finish")*(Answers!$A$3:$A$400<>"EXAMPLE")*Answers!$J$3:$K$400)/SUMPRODUCT((Answers!$B$3:$B$400="Finish")*(Answers!$A$3:$A$400<>"EXAMPLE")*(Answers!$J$3:$K$400<>"")),"") | E17: =IF(OR(B17="",D17=""),"",D17-B17)
A18: A7 Robots and coding are fun. | B18: =IFERROR(AVERAGEIFS(Answers!$J$3:$J$400,Answers!$B$3:$B$400,"Start",Answers!$A$3:$A$400,"<>EXAMPLE"),"") | C18: =IFERROR(AVERAGEIFS(Answers!$J$3:$J$400,Answers!$B$3:$B$400,"Halfway",Answers!$A$3:$A$400,"<>EXAMPLE"),"") | D18: =IFERROR(AVERAGEIFS(Answers!$J$3:$J$400,Answers!$B$3:$B$400,"Finish",Answers!$A$3:$A$400,"<>EXAMPLE"),"") | E18: =IF(OR(B18="",D18=""),"",D18-B18)
A19: A8 I could be an engineer or a programmer one day. | B19: =IFERROR(AVERAGEIFS(Answers!$K$3:$K$400,Answers!$B$3:$B$400,"Start",Answers!$A$3:$A$400,"<>EXAMPLE"),"") | C19: =IFERROR(AVERAGEIFS(Answers!$K$3:$K$400,Answers!$B$3:$B$400,"Halfway",Answers!$A$3:$A$400,"<>EXAMPLE"),"") | D19: =IFERROR(AVERAGEIFS(Answers!$K$3:$K$400,Answers!$B$3:$B$400,"Finish",Answers!$A$3:$A$400,"<>EXAMPLE"),"") | E19: =IF(OR(B19="",D19=""),"",D19-B19)
A21: Part 2: What do you know? (share answered right) | B21: Start | C21: Halfway | D21: Finish | E21: Change
A22: All eight questions | B22: =IFERROR(SUMPRODUCT((Answers!$B$3:$B$400="Start")*(Answers!$A$3:$A$400<>"EXAMPLE")*Answers!$L$3:$S$400)/SUMPRODUCT((Answers!$B$3:$B$400="Start")*(Answers!$A$3:$A$400<>"EXAMPLE")*(Answers!$L$3:$S$400<>"")),"") | C22: =IFERROR(SUMPRODUCT((Answers!$B$3:$B$400="Halfway")*(Answers!$A$3:$A$400<>"EXAMPLE")*Answers!$L$3:$S$400)/SUMPRODUCT((Answers!$B$3:$B$400="Halfway")*(Answers!$A$3:$A$400<>"EXAMPLE")*(Answers!$L$3:$S$400<>"")),"") | D22: =IFERROR(SUMPRODUCT((Answers!$B$3:$B$400="Finish")*(Answers!$A$3:$A$400<>"EXAMPLE")*Answers!$L$3:$S$400)/SUMPRODUCT((Answers!$B$3:$B$400="Finish")*(Answers!$A$3:$A$400<>"EXAMPLE")*(Answers!$L$3:$S$400<>"")),"") | E22: =IF(OR(B22="",D22=""),"",D22-B22)
A23: K1 (Lesson 1) A robot is a machine that can... | B23: =IFERROR(AVERAGEIFS(Answers!$L$3:$L$400,Answers!$B$3:$B$400,"Start",Answers!$A$3:$A$400,"<>EXAMPLE"),"") | C23: =IFERROR(AVERAGEIFS(Answers!$L$3:$L$400,Answers!$B$3:$B$400,"Halfway",Answers!$A$3:$A$400,"<>EXAMPLE"),"") | D23: =IFERROR(AVERAGEIFS(Answers!$L$3:$L$400,Answers!$B$3:$B$400,"Finish",Answers!$A$3:$A$400,"<>EXAMPLE"),"") | E23: =IF(OR(B23="",D23=""),"",D23-B23)
A24: K2 (Lesson 2) In a program, loop() runs... | B24: =IFERROR(AVERAGEIFS(Answers!$M$3:$M$400,Answers!$B$3:$B$400,"Start",Answers!$A$3:$A$400,"<>EXAMPLE"),"") | C24: =IFERROR(AVERAGEIFS(Answers!$M$3:$M$400,Answers!$B$3:$B$400,"Halfway",Answers!$A$3:$A$400,"<>EXAMPLE"),"") | D24: =IFERROR(AVERAGEIFS(Answers!$M$3:$M$400,Answers!$B$3:$B$400,"Finish",Answers!$A$3:$A$400,"<>EXAMPLE"),"") | E24: =IF(OR(B24="",D24=""),"",D24-B24)
A25: K3 (Lesson 3) Red light and green light mixed together make... | B25: =IFERROR(AVERAGEIFS(Answers!$N$3:$N$400,Answers!$B$3:$B$400,"Start",Answers!$A$3:$A$400,"<>EXAMPLE"),"") | C25: =IFERROR(AVERAGEIFS(Answers!$N$3:$N$400,Answers!$B$3:$B$400,"Halfway",Answers!$A$3:$A$400,"<>EXAMPLE"),"") | D25: =IFERROR(AVERAGEIFS(Answers!$N$3:$N$400,Answers!$B$3:$B$400,"Finish",Answers!$A$3:$A$400,"<>EXAMPLE"),"") | E25: =IF(OR(B25="",D25=""),"",D25-B25)
A26: K4 (Lesson 5) A Pathfinder turns right by... | B26: =IFERROR(AVERAGEIFS(Answers!$O$3:$O$400,Answers!$B$3:$B$400,"Start",Answers!$A$3:$A$400,"<>EXAMPLE"),"") | C26: =IFERROR(AVERAGEIFS(Answers!$O$3:$O$400,Answers!$B$3:$B$400,"Halfway",Answers!$A$3:$A$400,"<>EXAMPLE"),"") | D26: =IFERROR(AVERAGEIFS(Answers!$O$3:$O$400,Answers!$B$3:$B$400,"Finish",Answers!$A$3:$A$400,"<>EXAMPLE"),"") | E26: =IF(OR(B26="",D26=""),"",D26-B26)
A27: K5 (Lesson 6) 1000 milliseconds is... | B27: =IFERROR(AVERAGEIFS(Answers!$P$3:$P$400,Answers!$B$3:$B$400,"Start",Answers!$A$3:$A$400,"<>EXAMPLE"),"") | C27: =IFERROR(AVERAGEIFS(Answers!$P$3:$P$400,Answers!$B$3:$B$400,"Halfway",Answers!$A$3:$A$400,"<>EXAMPLE"),"") | D27: =IFERROR(AVERAGEIFS(Answers!$P$3:$P$400,Answers!$B$3:$B$400,"Finish",Answers!$A$3:$A$400,"<>EXAMPLE"),"") | E27: =IF(OR(B27="",D27=""),"",D27-B27)
A28: K6 (Lesson 7) A function is... | B28: =IFERROR(AVERAGEIFS(Answers!$Q$3:$Q$400,Answers!$B$3:$B$400,"Start",Answers!$A$3:$A$400,"<>EXAMPLE"),"") | C28: =IFERROR(AVERAGEIFS(Answers!$Q$3:$Q$400,Answers!$B$3:$B$400,"Halfway",Answers!$A$3:$A$400,"<>EXAMPLE"),"") | D28: =IFERROR(AVERAGEIFS(Answers!$Q$3:$Q$400,Answers!$B$3:$B$400,"Finish",Answers!$A$3:$A$400,"<>EXAMPLE"),"") | E28: =IF(OR(B28="",D28=""),"",D28-B28)
A29: K7 (Lesson 8) In if (buttonA()) { ... } else { ... } the else part happens when... | B29: =IFERROR(AVERAGEIFS(Answers!$R$3:$R$400,Answers!$B$3:$B$400,"Start",Answers!$A$3:$A$400,"<>EXAMPLE"),"") | C29: =IFERROR(AVERAGEIFS(Answers!$R$3:$R$400,Answers!$B$3:$B$400,"Halfway",Answers!$A$3:$A$400,"<>EXAMPLE"),"") | D29: =IFERROR(AVERAGEIFS(Answers!$R$3:$R$400,Answers!$B$3:$B$400,"Finish",Answers!$A$3:$A$400,"<>EXAMPLE"),"") | E29: =IF(OR(B29="",D29=""),"",D29-B29)
A30: K8 (Lesson 10) While a program is waiting in delay(), it... | B30: =IFERROR(AVERAGEIFS(Answers!$S$3:$S$400,Answers!$B$3:$B$400,"Start",Answers!$A$3:$A$400,"<>EXAMPLE"),"") | C30: =IFERROR(AVERAGEIFS(Answers!$S$3:$S$400,Answers!$B$3:$B$400,"Halfway",Answers!$A$3:$A$400,"<>EXAMPLE"),"") | D30: =IFERROR(AVERAGEIFS(Answers!$S$3:$S$400,Answers!$B$3:$B$400,"Finish",Answers!$A$3:$A$400,"<>EXAMPLE"),"") | E30: =IF(OR(B30="",D30=""),"",D30-B30)
A32: Lessons (average) | B32: Liked it | C32: How hard | D32: Answers | E32: Worth a look?
A33: Liked: 1 not much, 3 loved it. Hard: 1 too easy, 2 just right, 3 too hard.
A34: 1 Meet Pathfinder | B34: =IFERROR(AVERAGEIFS(Answers!$T$3:$T$400,Answers!$A$3:$A$400,"<>EXAMPLE"),"") | C34: =IFERROR(AVERAGEIFS(Answers!$AF$3:$AF$400,Answers!$A$3:$A$400,"<>EXAMPLE"),"") | D34: =COUNTIFS(Answers!$T$3:$T$400,"<>",Answers!$A$3:$A$400,"<>EXAMPLE") | E34: =IF(B34="","",TRIM(IF(C34>=2.5,"Too hard? ",IF(C34<=1.5,"Too easy? ",""))&IF(B34<2,"Not landing?","")))
A35: 2 Talking to Robots | B35: =IFERROR(AVERAGEIFS(Answers!$U$3:$U$400,Answers!$A$3:$A$400,"<>EXAMPLE"),"") | C35: =IFERROR(AVERAGEIFS(Answers!$AG$3:$AG$400,Answers!$A$3:$A$400,"<>EXAMPLE"),"") | D35: =COUNTIFS(Answers!$U$3:$U$400,"<>",Answers!$A$3:$A$400,"<>EXAMPLE") | E35: =IF(B35="","",TRIM(IF(C35>=2.5,"Too hard? ",IF(C35<=1.5,"Too easy? ",""))&IF(B35<2,"Not landing?","")))
A36: 3 Color Lab | B36: =IFERROR(AVERAGEIFS(Answers!$V$3:$V$400,Answers!$A$3:$A$400,"<>EXAMPLE"),"") | C36: =IFERROR(AVERAGEIFS(Answers!$AH$3:$AH$400,Answers!$A$3:$A$400,"<>EXAMPLE"),"") | D36: =COUNTIFS(Answers!$V$3:$V$400,"<>",Answers!$A$3:$A$400,"<>EXAMPLE") | E36: =IF(B36="","",TRIM(IF(C36>=2.5,"Too hard? ",IF(C36<=1.5,"Too easy? ",""))&IF(B36<2,"Not landing?","")))
A37: 4 Loops and Light Shows | B37: =IFERROR(AVERAGEIFS(Answers!$W$3:$W$400,Answers!$A$3:$A$400,"<>EXAMPLE"),"") | C37: =IFERROR(AVERAGEIFS(Answers!$AI$3:$AI$400,Answers!$A$3:$A$400,"<>EXAMPLE"),"") | D37: =COUNTIFS(Answers!$W$3:$W$400,"<>",Answers!$A$3:$A$400,"<>EXAMPLE") | E37: =IF(B37="","",TRIM(IF(C37>=2.5,"Too hard? ",IF(C37<=1.5,"Too easy? ",""))&IF(B37<2,"Not landing?","")))
A38: 5 Make It Move | B38: =IFERROR(AVERAGEIFS(Answers!$X$3:$X$400,Answers!$A$3:$A$400,"<>EXAMPLE"),"") | C38: =IFERROR(AVERAGEIFS(Answers!$AJ$3:$AJ$400,Answers!$A$3:$A$400,"<>EXAMPLE"),"") | D38: =COUNTIFS(Answers!$X$3:$X$400,"<>",Answers!$A$3:$A$400,"<>EXAMPLE") | E38: =IF(B38="","",TRIM(IF(C38>=2.5,"Too hard? ",IF(C38<=1.5,"Too easy? ",""))&IF(B38<2,"Not landing?","")))
A39: 6 Drive by Code | B39: =IFERROR(AVERAGEIFS(Answers!$Y$3:$Y$400,Answers!$A$3:$A$400,"<>EXAMPLE"),"") | C39: =IFERROR(AVERAGEIFS(Answers!$AK$3:$AK$400,Answers!$A$3:$A$400,"<>EXAMPLE"),"") | D39: =COUNTIFS(Answers!$Y$3:$Y$400,"<>",Answers!$A$3:$A$400,"<>EXAMPLE") | E39: =IF(B39="","",TRIM(IF(C39>=2.5,"Too hard? ",IF(C39<=1.5,"Too easy? ",""))&IF(B39<2,"Not landing?","")))
A40: 7 Mission to Mars | B40: =IFERROR(AVERAGEIFS(Answers!$Z$3:$Z$400,Answers!$A$3:$A$400,"<>EXAMPLE"),"") | C40: =IFERROR(AVERAGEIFS(Answers!$AL$3:$AL$400,Answers!$A$3:$A$400,"<>EXAMPLE"),"") | D40: =COUNTIFS(Answers!$Z$3:$Z$400,"<>",Answers!$A$3:$A$400,"<>EXAMPLE") | E40: =IF(B40="","",TRIM(IF(C40>=2.5,"Too hard? ",IF(C40<=1.5,"Too easy? ",""))&IF(B40<2,"Not landing?","")))
A41: 8 Wireless Control | B41: =IFERROR(AVERAGEIFS(Answers!$AA$3:$AA$400,Answers!$A$3:$A$400,"<>EXAMPLE"),"") | C41: =IFERROR(AVERAGEIFS(Answers!$AM$3:$AM$400,Answers!$A$3:$A$400,"<>EXAMPLE"),"") | D41: =COUNTIFS(Answers!$AA$3:$AA$400,"<>",Answers!$A$3:$A$400,"<>EXAMPLE") | E41: =IF(B41="","",TRIM(IF(C41>=2.5,"Too hard? ",IF(C41<=1.5,"Too easy? ",""))&IF(B41<2,"Not landing?","")))
A42: 9 Joystick Driving | B42: =IFERROR(AVERAGEIFS(Answers!$AB$3:$AB$400,Answers!$A$3:$A$400,"<>EXAMPLE"),"") | C42: =IFERROR(AVERAGEIFS(Answers!$AN$3:$AN$400,Answers!$A$3:$A$400,"<>EXAMPLE"),"") | D42: =COUNTIFS(Answers!$AB$3:$AB$400,"<>",Answers!$A$3:$A$400,"<>EXAMPLE") | E42: =IF(B42="","",TRIM(IF(C42>=2.5,"Too hard? ",IF(C42<=1.5,"Too easy? ",""))&IF(B42<2,"Not landing?","")))
A43: 10 Smart Lights | B43: =IFERROR(AVERAGEIFS(Answers!$AC$3:$AC$400,Answers!$A$3:$A$400,"<>EXAMPLE"),"") | C43: =IFERROR(AVERAGEIFS(Answers!$AO$3:$AO$400,Answers!$A$3:$A$400,"<>EXAMPLE"),"") | D43: =COUNTIFS(Answers!$AC$3:$AC$400,"<>",Answers!$A$3:$A$400,"<>EXAMPLE") | E43: =IF(B43="","",TRIM(IF(C43>=2.5,"Too hard? ",IF(C43<=1.5,"Too easy? ",""))&IF(B43<2,"Not landing?","")))
A44: 11 Design Challenge | B44: =IFERROR(AVERAGEIFS(Answers!$AD$3:$AD$400,Answers!$A$3:$A$400,"<>EXAMPLE"),"") | C44: =IFERROR(AVERAGEIFS(Answers!$AP$3:$AP$400,Answers!$A$3:$A$400,"<>EXAMPLE"),"") | D44: =COUNTIFS(Answers!$AD$3:$AD$400,"<>",Answers!$A$3:$A$400,"<>EXAMPLE") | E44: =IF(B44="","",TRIM(IF(C44>=2.5,"Too hard? ",IF(C44<=1.5,"Too easy? ",""))&IF(B44<2,"Not landing?","")))
...

Sheet Growth
A1: Each student, start to finish
A2: Type each Explorer code once in column A (yellow). The rest fills itself in from the Answers sheet.
A3: Explorer code | B3: About me, average of A1 to A8 (1 to 4) | F3: Part 2, questions right (out of 8)
B4: Start | C4: Halfway | D4: Finish | E4: Change | F4: Start | G4: Halfway | H4: Finish | I4: Change
A5: EXAMPLE | B5: =IF($A5="","",IFERROR(SUMPRODUCT((Answers!$A$3:$A$400=$A5)*(Answers!$B$3:$B$400="Start")*Answers!$D$3:$K$400)/SUMPRODUCT((Answers!$A$3:$A$400=$A5)*(Answers!$B$3:$B$400="Start")*(Answers!$D$3:$K$400<>"")),"")) | C5: =IF($A5="","",IFERROR(SUMPRODUCT((Answers!$A$3:$A$400=$A5)*(Answers!$B$3:$B$400="Halfway")*Answers!$D$3:$K$400)/SUMPRODUCT((Answers!$A$3:$A$400=$A5)*(Answers!$B$3:$B$400="Halfway")*(Answers!$D$3:$K$400<>"")),"")) | D5: =IF($A5="","",IFERROR(SUMPRODUCT((Answers!$A$3:$A$400=$A5)*(Answers!$B$3:$B$400="Finish")*Answers!$D$3:$K$400)/SUMPRODUCT((Answers!$A$3:$A$400=$A5)*(Answers!$B$3:$B$400="Finish")*(Answers!$D$3:$K$400<>"")),"")) | E5: =IF(OR(B5="",D5=""),"",D5-B5) | F5: =IF($A5="","",IF(COUNTIFS(Answers!$A$3:$A$400,$A5,Answers!$B$3:$B$400,"Start")=0,"",SUMPRODUCT((Answers!$A$3:$A$400=$A5)*(Answers!$B$3:$B$400="Start")*Answers!$L$3:$S$400))) | G5: =IF($A5="","",IF(COUNTIFS(Answers!$A$3:$A$400,$A5,Answers!$B$3:$B$400,"Halfway")=0,"",SUMPRODUCT((Answers!$A$3:$A$400=$A5)*(Answers!$B$3:$B$400="Halfway")*Answers!$L$3:$S$400))) | H5: =IF($A5="","",IF(COUNTIFS(Answers!$A$3:$A$400,$A5,Answers!$B$3:$B$400,"Finish")=0,"",SUMPRODUCT((Answers!$A$3:$A$400=$A5)*(Answers!$B$3:$B$400="Finish")*Answers!$L$3:$S$400))) | I5: =IF(OR(F5="",H5=""),"",H5-F5)
B6: =IF($A6="","",IFERROR(SUMPRODUCT((Answers!$A$3:$A$400=$A6)*(Answers!$B$3:$B$400="Start")*Answers!$D$3:$K$400)/SUMPRODUCT((Answers!$A$3:$A$400=$A6)*(Answers!$B$3:$B$400="Start")*(Answers!$D$3:$K$400<>"")),"")) | C6: =IF($A6="","",IFERROR(SUMPRODUCT((Answers!$A$3:$A$400=$A6)*(Answers!$B$3:$B$400="Halfway")*Answers!$D$3:$K$400)/SUMPRODUCT((Answers!$A$3:$A$400=$A6)*(Answers!$B$3:$B$400="Halfway")*(Answers!$D$3:$K$400<>"")),"")) | D6: =IF($A6="","",IFERROR(SUMPRODUCT((Answers!$A$3:$A$400=$A6)*(Answers!$B$3:$B$400="Finish")*Answers!$D$3:$K$400)/SUMPRODUCT((Answers!$A$3:$A$400=$A6)*(Answers!$B$3:$B$400="Finish")*(Answers!$D$3:$K$400<>"")),"")) | E6: =IF(OR(B6="",D6=""),"",D6-B6) | F6: =IF($A6="","",IF(COUNTIFS(Answers!$A$3:$A$400,$A6,Answers!$B$3:$B$400,"Start")=0,"",SUMPRODUCT((Answers!$A$3:$A$400=$A6)*(Answers!$B$3:$B$400="Start")*Answers!$L$3:$S$400))) | G6: =IF($A6="","",IF(COUNTIFS(Answers!$A$3:$A$400,$A6,Answers!$B$3:$B$400,"Halfway")=0,"",SUMPRODUCT((Answers!$A$3:$A$400=$A6)*(Answers!$B$3:$B$400="Halfway")*Answers!$L$3:$S$400))) | H6: =IF($A6="","",IF(COUNTIFS(Answers!$A$3:$A$400,$A6,Answers!$B$3:$B$400,"Finish")=0,"",SUMPRODUCT((Answers!$A$3:$A$400=$A6)*(Answers!$B$3:$B$400="Finish")*Answers!$L$3:$S$400))) | I6: =IF(OR(F6="",H6=""),"",H6-F6)
B7: =IF($A7="","",IFERROR(SUMPRODUCT((Answers!$A$3:$A$400=$A7)*(Answers!$B$3:$B$400="Start")*Answers!$D$3:$K$400)/SUMPRODUCT((Answers!$A$3:$A$400=$A7)*(Answers!$B$3:$B$400="Start")*(Answers!$D$3:$K$400<>"")),"")) | C7: =IF($A7="","",IFERROR(SUMPRODUCT((Answers!$A$3:$A$400=$A7)*(Answers!$B$3:$B$400="Halfway")*Answers!$D$3:$K$400)/SUMPRODUCT((Answers!$A$3:$A$400=$A7)*(Answers!$B$3:$B$400="Halfway")*(Answers!$D$3:$K$400<>"")),"")) | D7: =IF($A7="","",IFERROR(SUMPRODUCT((Answers!$A$3:$A$400=$A7)*(Answers!$B$3:$B$400="Finish")*Answers!$D$3:$K$400)/SUMPRODUCT((Answers!$A$3:$A$400=$A7)*(Answers!$B$3:$B$400="Finish")*(Answers!$D$3:$K$400<>"")),"")) | E7: =IF(OR(B7="",D7=""),"",D7-B7) | F7: =IF($A7="","",IF(COUNTIFS(Answers!$A$3:$A$400,$A7,Answers!$B$3:$B$400,"Start")=0,"",SUMPRODUCT((Answers!$A$3:$A$400=$A7)*(Answers!$B$3:$B$400="Start")*Answers!$L$3:$S$400))) | G7: =IF($A7="","",IF(COUNTIFS(Answers!$A$3:$A$400,$A7,Answers!$B$3:$B$400,"Halfway")=0,"",SUMPRODUCT((Answers!$A$3:$A$400=$A7)*(Answers!$B$3:$B$400="Halfway")*Answers!$L$3:$S$400))) | H7: =IF($A7="","",IF(COUNTIFS(Answers!$A$3:$A$400,$A7,Answers!$B$3:$B$400,"Finish")=0,"",SUMPRODUCT((Answers!$A$3:$A$400=$A7)*(Answers!$B$3:$B$400="Finish")*Answers!$L$3:$S$400))) | I7: =IF(OR(F7="",H7=""),"",H7-F7)
B8: =IF($A8="","",IFERROR(SUMPRODUCT((Answers!$A$3:$A$400=$A8)*(Answers!$B$3:$B$400="Start")*Answers!$D$3:$K$400)/SUMPRODUCT((Answers!$A$3:$A$400=$A8)*(Answers!$B$3:$B$400="Start")*(Answers!$D$3:$K$400<>"")),"")) | C8: =IF($A8="","",IFERROR(SUMPRODUCT((Answers!$A$3:$A$400=$A8)*(Answers!$B$3:$B$400="Halfway")*Answers!$D$3:$K$400)/SUMPRODUCT((Answers!$A$3:$A$400=$A8)*(Answers!$B$3:$B$400="Halfway")*(Answers!$D$3:$K$400<>"")),"")) | D8: =IF($A8="","",IFERROR(SUMPRODUCT((Answers!$A$3:$A$400=$A8)*(Answers!$B$3:$B$400="Finish")*Answers!$D$3:$K$400)/SUMPRODUCT((Answers!$A$3:$A$400=$A8)*(Answers!$B$3:$B$400="Finish")*(Answers!$D$3:$K$400<>"")),"")) | E8: =IF(OR(B8="",D8=""),"",D8-B8) | F8: =IF($A8="","",IF(COUNTIFS(Answers!$A$3:$A$400,$A8,Answers!$B$3:$B$400,"Start")=0,"",SUMPRODUCT((Answers!$A$3:$A$400=$A8)*(Answers!$B$3:$B$400="Start")*Answers!$L$3:$S$400))) | G8: =IF($A8="","",IF(COUNTIFS(Answers!$A$3:$A$400,$A8,Answers!$B$3:$B$400,"Halfway")=0,"",SUMPRODUCT((Answers!$A$3:$A$400=$A8)*(Answers!$B$3:$B$400="Halfway")*Answers!$L$3:$S$400))) | H8: =IF($A8="","",IF(COUNTIFS(Answers!$A$3:$A$400,$A8,Answers!$B$3:$B$400,"Finish")=0,"",SUMPRODUCT((Answers!$A$3:$A$400=$A8)*(Answers!$B$3:$B$400="Finish")*Answers!$L$3:$S$400))) | I8: =IF(OR(F8="",H8=""),"",H8-F8)
B9: =IF($A9="","",IFERROR(SUMPRODUCT((Answers!$A$3:$A$400=$A9)*(Answers!$B$3:$B$400="Start")*Answers!$D$3:$K$400)/SUMPRODUCT((Answers!$A$3:$A$400=$A9)*(Answers!$B$3:$B$400="Start")*(Answers!$D$3:$K$400<>"")),"")) | C9: =IF($A9="","",IFERROR(SUMPRODUCT((Answers!$A$3:$A$400=$A9)*(Answers!$B$3:$B$400="Halfway")*Answers!$D$3:$K$400)/SUMPRODUCT((Answers!$A$3:$A$400=$A9)*(Answers!$B$3:$B$400="Halfway")*(Answers!$D$3:$K$400<>"")),"")) | D9: =IF($A9="","",IFERROR(SUMPRODUCT((Answers!$A$3:$A$400=$A9)*(Answers!$B$3:$B$400="Finish")*Answers!$D$3:$K$400)/SUMPRODUCT((Answers!$A$3:$A$400=$A9)*(Answers!$B$3:$B$400="Finish")*(Answers!$D$3:$K$400<>"")),"")) | E9: =IF(OR(B9="",D9=""),"",D9-B9) | F9: =IF($A9="","",IF(COUNTIFS(Answers!$A$3:$A$400,$A9,Answers!$B$3:$B$400,"Start")=0,"",SUMPRODUCT((Answers!$A$3:$A$400=$A9)*(Answers!$B$3:$B$400="Start")*Answers!$L$3:$S$400))) | G9: =IF($A9="","",IF(COUNTIFS(Answers!$A$3:$A$400,$A9,Answers!$B$3:$B$400,"Halfway")=0,"",SUMPRODUCT((Answers!$A$3:$A$400=$A9)*(Answers!$B$3:$B$400="Halfway")*Answers!$L$3:$S$400))) | H9: =IF($A9="","",IF(COUNTIFS(Answers!$A$3:$A$400,$A9,Answers!$B$3:$B$400,"Finish")=0,"",SUMPRODUCT((Answers!$A$3:$A$400=$A9)*(Answers!$B$3:$B$400="Finish")*Answers!$L$3:$S$400))) | I9: =IF(OR(F9="",H9=""),"",H9-F9)
B10: =IF($A10="","",IFERROR(SUMPRODUCT((Answers!$A$3:$A$400=$A10)*(Answers!$B$3:$B$400="Start")*Answers!$D$3:$K$400)/SUMPRODUCT((Answers!$A$3:$A$400=$A10)*(Answers!$B$3:$B$400="Start")*(Answers!$D$3:$K$400<>"")),"")) | C10: =IF($A10="","",IFERROR(SUMPRODUCT((Answers!$A$3:$A$400=$A10)*(Answers!$B$3:$B$400="Halfway")*Answers!$D$3:$K$400)/SUMPRODUCT((Answers!$A$3:$A$400=$A10)*(Answers!$B$3:$B$400="Halfway")*(Answers!$D$3:$K$400<>"")),"")) | D10: =IF($A10="","",IFERROR(SUMPRODUCT((Answers!$A$3:$A$400=$A10)*(Answers!$B$3:$B$400="Finish")*Answers!$D$3:$K$400)/SUMPRODUCT((Answers!$A$3:$A$400=$A10)*(Answers!$B$3:$B$400="Finish")*(Answers!$D$3:$K$400<>"")),"")) | E10: =IF(OR(B10="",D10=""),"",D10-B10) | F10: =IF($A10="","",IF(COUNTIFS(Answers!$A$3:$A$400,$A10,Answers!$B$3:$B$400,"Start")=0,"",SUMPRODUCT((Answers!$A$3:$A$400=$A10)*(Answers!$B$3:$B$400="Start")*Answers!$L$3:$S$400))) | G10: =IF($A10="","",IF(COUNTIFS(Answers!$A$3:$A$400,$A10,Answers!$B$3:$B$400,"Halfway")=0,"",SUMPRODUCT((Answers!$A$3:$A$400=$A10)*(Answers!$B$3:$B$400="Halfway")*Answers!$L$3:$S$400))) | H10: =IF($A10="","",IF(COUNTIFS(Answers!$A$3:$A$400,$A10,Answers!$B$3:$B$400,"Finish")=0,"",SUMPRODUCT((Answers!$A$3:$A$400=$A10)*(Answers!$B$3:$B$400="Finish")*Answers!$L$3:$S$400))) | I10: =IF(OR(F10="",H10=""),"",H10-F10)
B11: =IF($A11="","",IFERROR(SUMPRODUCT((Answers!$A$3:$A$400=$A11)*(Answers!$B$3:$B$400="Start")*Answers!$D$3:$K$400)/SUMPRODUCT((Answers!$A$3:$A$400=$A11)*(Answers!$B$3:$B$400="Start")*(Answers!$D$3:$K$400<>"")),"")) | C11: =IF($A11="","",IFERROR(SUMPRODUCT((Answers!$A$3:$A$400=$A11)*(Answers!$B$3:$B$400="Halfway")*Answers!$D$3:$K$400)/SUMPRODUCT((Answers!$A$3:$A$400=$A11)*(Answers!$B$3:$B$400="Halfway")*(Answers!$D$3:$K$400<>"")),"")) | D11: =IF($A11="","",IFERROR(SUMPRODUCT((Answers!$A$3:$A$400=$A11)*(Answers!$B$3:$B$400="Finish")*Answers!$D$3:$K$400)/SUMPRODUCT((Answers!$A$3:$A$400=$A11)*(Answers!$B$3:$B$400="Finish")*(Answers!$D$3:$K$400<>"")),"")) | E11: =IF(OR(B11="",D11=""),"",D11-B11) | F11: =IF($A11="","",IF(COUNTIFS(Answers!$A$3:$A$400,$A11,Answers!$B$3:$B$400,"Start")=0,"",SUMPRODUCT((Answers!$A$3:$A$400=$A11)*(Answers!$B$3:$B$400="Start")*Answers!$L$3:$S$400))) | G11: =IF($A11="","",IF(COUNTIFS(Answers!$A$3:$A$400,$A11,Answers!$B$3:$B$400,"Halfway")=0,"",SUMPRODUCT((Answers!$A$3:$A$400=$A11)*(Answers!$B$3:$B$400="Halfway")*Answers!$L$3:$S$400))) | H11: =IF($A11="","",IF(COUNTIFS(Answers!$A$3:$A$400,$A11,Answers!$B$3:$B$400,"Finish")=0,"",SUMPRODUCT((Answers!$A$3:$A$400=$A11)*(Answers!$B$3:$B$400="Finish")*Answers!$L$3:$S$400))) | I11: =IF(OR(F11="",H11=""),"",H11-F11)
B12: =IF($A12="","",IFERROR(SUMPRODUCT((Answers!$A$3:$A$400=$A12)*(Answers!$B$3:$B$400="Start")*Answers!$D$3:$K$400)/SUMPRODUCT((Answers!$A$3:$A$400=$A12)*(Answers!$B$3:$B$400="Start")*(Answers!$D$3:$K$400<>"")),"")) | C12: =IF($A12="","",IFERROR(SUMPRODUCT((Answers!$A$3:$A$400=$A12)*(Answers!$B$3:$B$400="Halfway")*Answers!$D$3:$K$400)/SUMPRODUCT((Answers!$A$3:$A$400=$A12)*(Answers!$B$3:$B$400="Halfway")*(Answers!$D$3:$K$400<>"")),"")) | D12: =IF($A12="","",IFERROR(SUMPRODUCT((Answers!$A$3:$A$400=$A12)*(Answers!$B$3:$B$400="Finish")*Answers!$D$3:$K$400)/SUMPRODUCT((Answers!$A$3:$A$400=$A12)*(Answers!$B$3:$B$400="Finish")*(Answers!$D$3:$K$400<>"")),"")) | E12: =IF(OR(B12="",D12=""),"",D12-B12) | F12: =IF($A12="","",IF(COUNTIFS(Answers!$A$3:$A$400,$A12,Answers!$B$3:$B$400,"Start")=0,"",SUMPRODUCT((Answers!$A$3:$A$400=$A12)*(Answers!$B$3:$B$400="Start")*Answers!$L$3:$S$400))) | G12: =IF($A12="","",IF(COUNTIFS(Answers!$A$3:$A$400,$A12,Answers!$B$3:$B$400,"Halfway")=0,"",SUMPRODUCT((Answers!$A$3:$A$400=$A12)*(Answers!$B$3:$B$400="Halfway")*Answers!$L$3:$S$400))) | H12: =IF($A12="","",IF(COUNTIFS(Answers!$A$3:$A$400,$A12,Answers!$B$3:$B$400,"Finish")=0,"",SUMPRODUCT((Answers!$A$3:$A$400=$A12)*(Answers!$B$3:$B$400="Finish")*Answers!$L$3:$S$400))) | I12: =IF(OR(F12="",H12=""),"",H12-F12)
B13: =IF($A13="","",IFERROR(SUMPRODUCT((Answers!$A$3:$A$400=$A13)*(Answers!$B$3:$B$400="Start")*Answers!$D$3:$K$400)/SUMPRODUCT((Answers!$A$3:$A$400=$A13)*(Answers!$B$3:$B$400="Start")*(Answers!$D$3:$K$400<>"")),"")) | C13: =IF($A13="","",IFERROR(SUMPRODUCT((Answers!$A$3:$A$400=$A13)*(Answers!$B$3:$B$400="Halfway")*Answers!$D$3:$K$400)/SUMPRODUCT((Answers!$A$3:$A$400=$A13)*(Answers!$B$3:$B$400="Halfway")*(Answers!$D$3:$K$400<>"")),"")) | D13: =IF($A13="","",IFERROR(SUMPRODUCT((Answers!$A$3:$A$400=$A13)*(Answers!$B$3:$B$400="Finish")*Answers!$D$3:$K$400)/SUMPRODUCT((Answers!$A$3:$A$400=$A13)*(Answers!$B$3:$B$400="Finish")*(Answers!$D$3:$K$400<>"")),"")) | E13: =IF(OR(B13="",D13=""),"",D13-B13) | F13: =IF($A13="","",IF(COUNTIFS(Answers!$A$3:$A$400,$A13,Answers!$B$3:$B$400,"Start")=0,"",SUMPRODUCT((Answers!$A$3:$A$400=$A13)*(Answers!$B$3:$B$400="Start")*Answers!$L$3:$S$400))) | G13: =IF($A13="","",IF(COUNTIFS(Answers!$A$3:$A$400,$A13,Answers!$B$3:$B$400,"Halfway")=0,"",SUMPRODUCT((Answers!$A$3:$A$400=$A13)*(Answers!$B$3:$B$400="Halfway")*Answers!$L$3:$S$400))) | H13: =IF($A13="","",IF(COUNTIFS(Answers!$A$3:$A$400,$A13,Answers!$B$3:$B$400,"Finish")=0,"",SUMPRODUCT((Answers!$A$3:$A$400=$A13)*(Answers!$B$3:$B$400="Finish")*Answers!$L$3:$S$400))) | I13: =IF(OR(F13="",H13=""),"",H13-F13)
B14: =IF($A14="","",IFERROR(SUMPRODUCT((Answers!$A$3:$A$400=$A14)*(Answers!$B$3:$B$400="Start")*Answers!$D$3:$K$400)/SUMPRODUCT((Answers!$A$3:$A$400=$A14)*(Answers!$B$3:$B$400="Start")*(Answers!$D$3:$K$400<>"")),"")) | C14: =IF($A14="","",IFERROR(SUMPRODUCT((Answers!$A$3:$A$400=$A14)*(Answers!$B$3:$B$400="Halfway")*Answers!$D$3:$K$400)/SUMPRODUCT((Answers!$A$3:$A$400=$A14)*(Answers!$B$3:$B$400="Halfway")*(Answers!$D$3:$K$400<>"")),"")) | D14: =IF($A14="","",IFERROR(SUMPRODUCT((Answers!$A$3:$A$400=$A14)*(Answers!$B$3:$B$400="Finish")*Answers!$D$3:$K$400)/SUMPRODUCT((Answers!$A$3:$A$400=$A14)*(Answers!$B$3:$B$400="Finish")*(Answers!$D$3:$K$400<>"")),"")) | E14: =IF(OR(B14="",D14=""),"",D14-B14) | F14: =IF($A14="","",IF(COUNTIFS(Answers!$A$3:$A$400,$A14,Answers!$B$3:$B$400,"Start")=0,"",SUMPRODUCT((Answers!$A$3:$A$400=$A14)*(Answers!$B$3:$B$400="Start")*Answers!$L$3:$S$400))) | G14: =IF($A14="","",IF(COUNTIFS(Answers!$A$3:$A$400,$A14,Answers!$B$3:$B$400,"Halfway")=0,"",SUMPRODUCT((Answers!$A$3:$A$400=$A14)*(Answers!$B$3:$B$400="Halfway")*Answers!$L$3:$S$400))) | H14: =IF($A14="","",IF(COUNTIFS(Answers!$A$3:$A$400,$A14,Answers!$B$3:$B$400,"Finish")=0,"",SUMPRODUCT((Answers!$A$3:$A$400=$A14)*(Answers!$B$3:$B$400="Finish")*Answers!$L$3:$S$400))) | I14: =IF(OR(F14="",H14=""),"",H14-F14)
B15: =IF($A15="","",IFERROR(SUMPRODUCT((Answers!$A$3:$A$400=$A15)*(Answers!$B$3:$B$400="Start")*Answers!$D$3:$K$400)/SUMPRODUCT((Answers!$A$3:$A$400=$A15)*(Answers!$B$3:$B$400="Start")*(Answers!$D$3:$K$400<>"")),"")) | C15: =IF($A15="","",IFERROR(SUMPRODUCT((Answers!$A$3:$A$400=$A15)*(Answers!$B$3:$B$400="Halfway")*Answers!$D$3:$K$400)/SUMPRODUCT((Answers!$A$3:$A$400=$A15)*(Answers!$B$3:$B$400="Halfway")*(Answers!$D$3:$K$400<>"")),"")) | D15: =IF($A15="","",IFERROR(SUMPRODUCT((Answers!$A$3:$A$400=$A15)*(Answers!$B$3:$B$400="Finish")*Answers!$D$3:$K$400)/SUMPRODUCT((Answers!$A$3:$A$400=$A15)*(Answers!$B$3:$B$400="Finish")*(Answers!$D$3:$K$400<>"")),"")) | E15: =IF(OR(B15="",D15=""),"",D15-B15) | F15: =IF($A15="","",IF(COUNTIFS(Answers!$A$3:$A$400,$A15,Answers!$B$3:$B$400,"Start")=0,"",SUMPRODUCT((Answers!$A$3:$A$400=$A15)*(Answers!$B$3:$B$400="Start")*Answers!$L$3:$S$400))) | G15: =IF($A15="","",IF(COUNTIFS(Answers!$A$3:$A$400,$A15,Answers!$B$3:$B$400,"Halfway")=0,"",SUMPRODUCT((Answers!$A$3:$A$400=$A15)*(Answers!$B$3:$B$400="Halfway")*Answers!$L$3:$S$400))) | H15: =IF($A15="","",IF(COUNTIFS(Answers!$A$3:$A$400,$A15,Answers!$B$3:$B$400,"Finish")=0,"",SUMPRODUCT((Answers!$A$3:$A$400=$A15)*(Answers!$B$3:$B$400="Finish")*Answers!$L$3:$S$400))) | I15: =IF(OR(F15="",H15=""),"",H15-F15)
B16: =IF($A16="","",IFERROR(SUMPRODUCT((Answers!$A$3:$A$400=$A16)*(Answers!$B$3:$B$400="Start")*Answers!$D$3:$K$400)/SUMPRODUCT((Answers!$A$3:$A$400=$A16)*(Answers!$B$3:$B$400="Start")*(Answers!$D$3:$K$400<>"")),"")) | C16: =IF($A16="","",IFERROR(SUMPRODUCT((Answers!$A$3:$A$400=$A16)*(Answers!$B$3:$B$400="Halfway")*Answers!$D$3:$K$400)/SUMPRODUCT((Answers!$A$3:$A$400=$A16)*(Answers!$B$3:$B$400="Halfway")*(Answers!$D$3:$K$400<>"")),"")) | D16: =IF($A16="","",IFERROR(SUMPRODUCT((Answers!$A$3:$A$400=$A16)*(Answers!$B$3:$B$400="Finish")*Answers!$D$3:$K$400)/SUMPRODUCT((Answers!$A$3:$A$400=$A16)*(Answers!$B$3:$B$400="Finish")*(Answers!$D$3:$K$400<>"")),"")) | E16: =IF(OR(B16="",D16=""),"",D16-B16) | F16: =IF($A16="","",IF(COUNTIFS(Answers!$A$3:$A$400,$A16,Answers!$B$3:$B$400,"Start")=0,"",SUMPRODUCT((Answers!$A$3:$A$400=$A16)*(Answers!$B$3:$B$400="Start")*Answers!$L$3:$S$400))) | G16: =IF($A16="","",IF(COUNTIFS(Answers!$A$3:$A$400,$A16,Answers!$B$3:$B$400,"Halfway")=0,"",SUMPRODUCT((Answers!$A$3:$A$400=$A16)*(Answers!$B$3:$B$400="Halfway")*Answers!$L$3:$S$400))) | H16: =IF($A16="","",IF(COUNTIFS(Answers!$A$3:$A$400,$A16,Answers!$B$3:$B$400,"Finish")=0,"",SUMPRODUCT((Answers!$A$3:$A$400=$A16)*(Answers!$B$3:$B$400="Finish")*Answers!$L$3:$S$400))) | I16: =IF(OR(F16="",H16=""),"",H16-F16)
B17: =IF($A17="","",IFERROR(SUMPRODUCT((Answers!$A$3:$A$400=$A17)*(Answers!$B$3:$B$400="Start")*Answers!$D$3:$K$400)/SUMPRODUCT((Answers!$A$3:$A$400=$A17)*(Answers!$B$3:$B$400="Start")*(Answers!$D$3:$K$400<>"")),"")) | C17: =IF($A17="","",IFERROR(SUMPRODUCT((Answers!$A$3:$A$400=$A17)*(Answers!$B$3:$B$400="Halfway")*Answers!$D$3:$K$400)/SUMPRODUCT((Answers!$A$3:$A$400=$A17)*(Answers!$B$3:$B$400="Halfway")*(Answers!$D$3:$K$400<>"")),"")) | D17: =IF($A17="","",IFERROR(SUMPRODUCT((Answers!$A$3:$A$400=$A17)*(Answers!$B$3:$B$400="Finish")*Answers!$D$3:$K$400)/SUMPRODUCT((Answers!$A$3:$A$400=$A17)*(Answers!$B$3:$B$400="Finish")*(Answers!$D$3:$K$400<>"")),"")) | E17: =IF(OR(B17="",D17=""),"",D17-B17) | F17: =IF($A17="","",IF(COUNTIFS(Answers!$A$3:$A$400,$A17,Answers!$B$3:$B$400,"Start")=0,"",SUMPRODUCT((Answers!$A$3:$A$400=$A17)*(Answers!$B$3:$B$400="Start")*Answers!$L$3:$S$400))) | G17: =IF($A17="","",IF(COUNTIFS(Answers!$A$3:$A$400,$A17,Answers!$B$3:$B$400,"Halfway")=0,"",SUMPRODUCT((Answers!$A$3:$A$400=$A17)*(Answers!$B$3:$B$400="Halfway")*Answers!$L$3:$S$400))) | H17: =IF($A17="","",IF(COUNTIFS(Answers!$A$3:$A$400,$A17,Answers!$B$3:$B$400,"Finish")=0,"",SUMPRODUCT((Answers!$A$3:$A$400=$A17)*(Answers!$B$3:$B$400="Finish")*Answers!$L$3:$S$400))) | I17: =IF(OR(F17="",H17=""),"",H17-F17)
... B64: =IF($A64="","",IFERROR(SUMPRODUCT((Answers!$A$3:$A$400=$A64)*(Answers!$B$3:$B$400="Start")*Answers!$D$3:$K$400)/SUMPRODUCT((Answers!$A$3:$A$400=$A64)*(Answers!$B$3:$B$400="Start")*(Answers!$D$3:$K$400<>"")),"")) | C64: =IF($A64="","",IFERROR(SUMPRODUCT((Answers!$A$3:$A$400=$A64)*(Answers!$B$3:$B$400="Halfway")*Answers!$D$3:$K$400)/SUMPRODUCT((Answers!$A$3:$A$400=$A64)*(Answers!$B$3:$B$400="Halfway")*(Answers!$D$3:$K$400<>"")),"")) | D64: =IF($A64="","",IFERROR(SUMPRODUCT((Answers!$A$3:$A$400=$A64)*(Answers!$B$3:$B$400="Finish")*Answers!$D$3:$K$400)/SUMPRODUCT((Answers!$A$3:$A$400=$A64)*(Answers!$B$3:$B$400="Finish")*(Answers!$D$3:$K$400<>"")),"")) | E64: =IF(OR(B64="",D64=""),"",D64-B64) | F64: =IF($A64="","",IF(COUNTIFS(Answers!$A$3:$A$400,$A64,Answers!$B$3:$B$400,"Start")=0,"",SUMPRODUCT((Answers!$A$3:$A$400=$A64)*(Answers!$B$3:$B$400="Start")*Answers!$L$3:$S$400))) | G64: =IF($A64="","",IF(COUNTIFS(Answers!$A$3:$A$400,$A64,Answers!$B$3:$B$400,"Halfway")=0,"",SUMPRODUCT((Answers!$A$3:$A$400=$A64)*(Answers!$B$3:$B$400="Halfway")*Answers!$L$3:$S$400))) | H64: =IF($A64="","",IF(COUNTIFS(Answers!$A$3:$A$400,$A64,Answers!$B$3:$B$400,"Finish")=0,"",SUMPRODUCT((Answers!$A$3:$A$400=$A64)*(Answers!$B$3:$B$400="Finish")*Answers!$L$3:$S$400))) | I64: =IF(OR(F64="",H64=""),"",H64-F64)
